<?xml version='1.0' encoding='utf-8'?>
<robot name="rocker_bogie_rover_visual">
  <link name="base_link">
    <visual>
      <origin xyz="0 0 0.10" rpy="0 0 0" />
      <geometry>
        <box size="0.75 0.42 0.22" />
      </geometry>
      <material name="chassis_lightgrey">
        <color rgba="0.82 0.80 0.78 1.0" />
      </material>
    </visual>
    <visual>
      <origin xyz="0.38 0 0.12" rpy="0 0.35 0" />
      <geometry>
        <box size="0.12 0.42 0.18" />
      </geometry>
      <material name="chassis_lightgrey" />
    </visual>
    <visual>
      <origin xyz="0.42 0 0.02" rpy="0 0.6 0" />
      <geometry>
        <box size="0.06 0.40 0.10" />
      </geometry>
      <material name="chassis_accent">
        <color rgba="0.72 0.70 0.67 1.0" />
      </material>
    </visual>
    <visual>
      <origin xyz="-0.38 0 0.12" rpy="0 -0.35 0" />
      <geometry>
        <box size="0.12 0.42 0.18" />
      </geometry>
      <material name="chassis_lightgrey" />
    </visual>
    <visual>
      <origin xyz="-0.42 0 0.02" rpy="0 -0.6 0" />
      <geometry>
        <box size="0.06 0.40 0.10" />
      </geometry>
      <material name="chassis_accent" />
    </visual>
    <visual>
      <origin xyz="0 0.215 0.10" rpy="0 0 0" />
      <geometry>
        <box size="0.70 0.01 0.20" />
      </geometry>
      <material name="panel_line">
        <color rgba="0.60 0.58 0.55 1.0" />
      </material>
    </visual>
    <visual>
      <origin xyz="0 -0.215 0.10" rpy="0 0 0" />
      <geometry>
        <box size="0.70 0.01 0.20" />
      </geometry>
      <material name="panel_line" />
    </visual>
    <visual>
      <origin xyz="0 0 0.225" rpy="0 0 0" />
      <geometry>
        <box size="0.60 0.36 0.03" />
      </geometry>
      <material name="deck_carbon">
        <color rgba="0.10 0.10 0.10 1.0" />
      </material>
    </visual>
    <visual>
      <origin xyz="0 0 0.215" rpy="0 0 0" />
      <geometry>
        <box size="0.62 0.38 0.01" />
      </geometry>
      <material name="trim_gold">
        <color rgba="0.85 0.72 0.30 1.0" />
      </material>
    </visual>
    <visual>
      <origin xyz="-0.15 0.10 0.26" rpy="0 0 0" />
      <geometry>
        <box size="0.12 0.10 0.04" />
      </geometry>
      <material name="electronics_grey">
        <color rgba="0.35 0.35 0.38 1.0" />
      </material>
    </visual>
    <visual>
      <origin xyz="-0.15 0.10 0.285" rpy="0 0 0" />
      <geometry>
        <box size="0.08 0.06 0.005" />
      </geometry>
      <material name="vent_dark">
        <color rgba="0.15 0.15 0.15 1.0" />
      </material>
    </visual>
    <visual>
      <origin xyz="-0.15 -0.10 0.26" rpy="0 0 0" />
      <geometry>
        <box size="0.14 0.10 0.04" />
      </geometry>
      <material name="battery_blue">
        <color rgba="0.25 0.30 0.45 1.0" />
      </material>
    </visual>
    <visual>
      <origin xyz="0 0.28 -0.04" rpy="0 0 0" />
      <geometry>
        <box size="0.12 0.07 0.16" />
      </geometry>
      <material name="structure_dgrey">
        <color rgba="0.28 0.28 0.30 1.0" />
      </material>
    </visual>
    <visual>
      <origin xyz="0 0.28 0.04" rpy="0 0 0" />
      <geometry>
        <box size="0.14 0.08 0.01" />
      </geometry>
      <material name="structure_dgrey" />
    </visual>
    <visual>
      <origin xyz="0 -0.28 -0.04" rpy="0 0 0" />
      <geometry>
        <box size="0.12 0.07 0.16" />
      </geometry>
      <material name="structure_dgrey" />
    </visual>
    <visual>
      <origin xyz="0 -0.28 0.04" rpy="0 0 0" />
      <geometry>
        <box size="0.14 0.08 0.01" />
      </geometry>
      <material name="structure_dgrey" />
    </visual>
    <visual>
      <origin xyz="0 0 0.0" rpy="1.5708 0 0" />
      <geometry>
        <cylinder radius="0.030" length="0.64" />
      </geometry>
      <material name="diff_orange">
        <color rgba="1.0 0.65 0.0 1.0" />
      </material>
    </visual>
    <visual>
      <origin xyz="0 0.30 0.0" rpy="1.5708 0 0" />
      <geometry>
        <cylinder radius="0.052" length="0.08" />
      </geometry>
      <material name="bearing_dark">
        <color rgba="0.16 0.16 0.16 1.0" />
      </material>
    </visual>
    <visual>
      <origin xyz="0 0.265 0.0" rpy="1.5708 0 0" />
      <geometry>
        <cylinder radius="0.060" length="0.012" />
      </geometry>
      <material name="bearing_dark" />
    </visual>
    <visual>
      <origin xyz="0 -0.30 0.0" rpy="1.5708 0 0" />
      <geometry>
        <cylinder radius="0.052" length="0.08" />
      </geometry>
      <material name="bearing_dark" />
    </visual>
    <visual>
      <origin xyz="0 -0.265 0.0" rpy="1.5708 0 0" />
      <geometry>
        <cylinder radius="0.060" length="0.012" />
      </geometry>
      <material name="bearing_dark" />
    </visual>
    <visual>
      <origin xyz="0 0 0.0" rpy="0 0 0" />
      <geometry>
        <box size="0.09 0.09 0.08" />
      </geometry>
      <material name="support_block">
        <color rgba="0.20 0.20 0.22 1.0" />
      </material>
    </visual>
    <collision>
      <origin xyz="0 0 0.10" rpy="0 0 0" />
      <geometry>
        <box size="0.75 0.42 0.22" />
      </geometry>
    </collision>
    <inertial>
      <mass value="20.0" />
      <origin xyz="0 0 -0.02" rpy="0 0 0" />
      <inertia ixx="0.375" ixy="0.0" ixz="0.0" iyy="1.019" iyz="0.0" izz="1.231" />
    </inertial>
  </link>
  <link name="camera_mast">
    <visual>
      <origin xyz="0 0 0.14" rpy="0 0 0" />
      <geometry>
        <cylinder radius="0.015" length="0.28" />
      </geometry>
      <material name="mast_silver">
        <color rgba="0.65 0.65 0.68 1.0" />
      </material>
    </visual>
    <visual>
      <origin xyz="0 0 0.30" rpy="0 0 0" />
      <geometry>
        <box size="0.06 0.08 0.04" />
      </geometry>
      <material name="cam_housing">
        <color rgba="0.18 0.18 0.20 1.0" />
      </material>
    </visual>
    <visual>
      <origin xyz="0.035 0.02 0.30" rpy="0 1.5708 0" />
      <geometry>
        <cylinder radius="0.012" length="0.01" />
      </geometry>
      <material name="lens_blue">
        <color rgba="0.15 0.25 0.55 1.0" />
      </material>
    </visual>
    <visual>
      <origin xyz="0.035 -0.02 0.30" rpy="0 1.5708 0" />
      <geometry>
        <cylinder radius="0.012" length="0.01" />
      </geometry>
      <material name="lens_blue" />
    </visual>
    <visual>
      <origin xyz="0 0 0.275" rpy="0 0 0" />
      <geometry>
        <cylinder radius="0.020" length="0.02" />
      </geometry>
      <material name="mast_joint_dark">
        <color rgba="0.12 0.12 0.12 1.0" />
      </material>
    </visual>
    <inertial>
      <mass value="0.001" />
      <origin xyz="0 0 0.15" rpy="0 0 0" />
      <inertia ixx="0.000001" ixy="0.0" ixz="0.0" iyy="0.000001" iyz="0.0" izz="0.000001" />
    </inertial>
  </link>
  <joint name="camera_mast_joint" type="fixed">
    <parent link="base_link" />
    <child link="camera_mast" />
    <origin xyz="0.20 0 0.24" rpy="0 0 0" />
  </joint>
  <link name="antenna">
    <visual>
      <origin xyz="0 0 0.10" rpy="0 -0.15 0" />
      <geometry>
        <cylinder radius="0.006" length="0.20" />
      </geometry>
      <material name="antenna_silver">
        <color rgba="0.70 0.70 0.72 1.0" />
      </material>
    </visual>
    <visual>
      <origin xyz="0.015 0 0.21" rpy="0 0 0" />
      <geometry>
        <cylinder radius="0.010" length="0.015" />
      </geometry>
      <material name="antenna_tip_red">
        <color rgba="0.85 0.15 0.10 1.0" />
      </material>
    </visual>
    <visual>
      <origin xyz="0 0 0.0" rpy="0 0 0" />
      <geometry>
        <cylinder radius="0.012" length="0.02" />
      </geometry>
      <material name="antenna_base">
        <color rgba="0.25 0.25 0.25 1.0" />
      </material>
    </visual>
    <inertial>
      <mass value="0.001" />
      <origin xyz="0 0 0.10" rpy="0 0 0" />
      <inertia ixx="0.000001" ixy="0.0" ixz="0.0" iyy="0.000001" iyz="0.0" izz="0.000001" />
    </inertial>
  </link>
  <joint name="antenna_joint" type="fixed">
    <parent link="base_link" />
    <child link="antenna" />
    <origin xyz="-0.25 0.12 0.24" rpy="0 0 0" />
  </joint>
  <link name="sensor_box">
    <visual>
      <origin xyz="0 0 0.02" rpy="0 0 0" />
      <geometry>
        <box size="0.10 0.06 0.04" />
      </geometry>
      <material name="sensor_grey">
        <color rgba="0.40 0.40 0.42 1.0" />
      </material>
    </visual>
    <visual>
      <origin xyz="0.052 0 0.02" rpy="0 1.5708 0" />
      <geometry>
        <cylinder radius="0.018" length="0.005" />
      </geometry>
      <material name="sensor_lens">
        <color rgba="0.10 0.15 0.30 1.0" />
      </material>
    </visual>
    <visual>
      <origin xyz="0 0 -0.005" rpy="0 0 0" />
      <geometry>
        <box size="0.06 0.08 0.01" />
      </geometry>
      <material name="bracket_dark">
        <color rgba="0.20 0.20 0.20 1.0" />
      </material>
    </visual>
    <inertial>
      <mass value="0.001" />
      <origin xyz="0 0 0.02" rpy="0 0 0" />
      <inertia ixx="0.000001" ixy="0.0" ixz="0.0" iyy="0.000001" iyz="0.0" izz="0.000001" />
    </inertial>
  </link>
  <joint name="sensor_box_joint" type="fixed">
    <parent link="base_link" />
    <child link="sensor_box" />
    <origin xyz="0.35 0 0.14" rpy="0 0 0" />
  </joint>
  <link name="left_rocker">
    <visual>
      <origin xyz="0.15 0 -0.06" rpy="0 0.20 0" />
      <geometry>
        <box size="0.46 0.08 0.065" />
      </geometry>
      <material name="rocker_metallic">
        <color rgba="0.45 0.43 0.42 1.0" />
      </material>
    </visual>
    <visual>
      <origin xyz="0.15 0 -0.03" rpy="0 0.20 0" />
      <geometry>
        <box size="0.44 0.07 0.008" />
      </geometry>
      <material name="rocker_highlight">
        <color rgba="0.55 0.53 0.50 1.0" />
      </material>
    </visual>
    <visual>
      <origin xyz="0 0 0" rpy="1.5708 0 0" />
      <geometry>
        <cylinder radius="0.056" length="0.09" />
      </geometry>
      <material name="hub_metallic">
        <color rgba="0.20 0.20 0.22 1.0" />
      </material>
    </visual>
    <visual>
      <origin xyz="0 0.048 0" rpy="1.5708 0 0" />
      <geometry>
        <cylinder radius="0.065" length="0.012" />
      </geometry>
      <material name="hub_metallic" />
    </visual>
    <visual>
      <origin xyz="-0.05 0 0.0" rpy="1.5708 0 0" />
      <geometry>
        <cylinder radius="0.050" length="0.085" />
      </geometry>
      <material name="hub_metallic" />
    </visual>
    <visual>
      <origin xyz="-0.05 0.045 0.0" rpy="1.5708 0 0" />
      <geometry>
        <cylinder radius="0.058" length="0.010" />
      </geometry>
      <material name="hub_metallic" />
    </visual>
    <visual>
      <origin xyz="0.35 0 -0.15" rpy="1.5708 0 0" />
      <geometry>
        <cylinder radius="0.042" length="0.085" />
      </geometry>
      <material name="hub_metallic" />
    </visual>
    <visual>
      <origin xyz="0.35 0.045 -0.15" rpy="1.5708 0 0" />
      <geometry>
        <cylinder radius="0.050" length="0.010" />
      </geometry>
      <material name="hub_metallic" />
    </visual>
    <visual>
      <origin xyz="0.32 0 -0.10" rpy="0 1.20 0" />
      <geometry>
        <box size="0.13 0.045 0.040" />
      </geometry>
      <material name="rocker_metallic" />
    </visual>
    <collision>
      <origin xyz="0.15 0 -0.06" rpy="0 0 0" />
      <geometry>
        <box size="0.44 0.07 0.055" />
      </geometry>
    </collision>
    <inertial>
      <mass value="2.8" />
      <origin xyz="0.15 0 -0.06" rpy="0 0 0" />
      <inertia ixx="0.00183" ixy="0.0" ixz="0.0" iyy="0.04586" iyz="0.0" izz="0.04630" />
    </inertial>
  </link>
  <joint name="left_rocker_joint" type="revolute">
    <parent link="base_link" />
    <child link="left_rocker" />
    <origin xyz="0 0.30 0.0" rpy="0 0 0" />
    <axis xyz="0 1 0" />
    <limit lower="-0.5" upper="0.5" effort="200" velocity="1.5" />
    <dynamics damping="15.0" friction="2.0" spring_reference="0.0" spring_stiffness="150.0" />
  </joint>
  <link name="right_rocker">
    <visual>
      <origin xyz="0.15 0 -0.06" rpy="0 0.20 0" />
      <geometry>
        <box size="0.46 0.08 0.065" />
      </geometry>
      <material name="rocker_metallic" />
    </visual>
    <visual>
      <origin xyz="0.15 0 -0.03" rpy="0 0.20 0" />
      <geometry>
        <box size="0.44 0.07 0.008" />
      </geometry>
      <material name="rocker_highlight" />
    </visual>
    <visual>
      <origin xyz="0 0 0" rpy="1.5708 0 0" />
      <geometry>
        <cylinder radius="0.056" length="0.09" />
      </geometry>
      <material name="hub_metallic" />
    </visual>
    <visual>
      <origin xyz="0 -0.048 0" rpy="1.5708 0 0" />
      <geometry>
        <cylinder radius="0.065" length="0.012" />
      </geometry>
      <material name="hub_metallic" />
    </visual>
    <visual>
      <origin xyz="-0.05 0 0.0" rpy="1.5708 0 0" />
      <geometry>
        <cylinder radius="0.050" length="0.085" />
      </geometry>
      <material name="hub_metallic" />
    </visual>
    <visual>
      <origin xyz="-0.05 -0.045 0.0" rpy="1.5708 0 0" />
      <geometry>
        <cylinder radius="0.058" length="0.010" />
      </geometry>
      <material name="hub_metallic" />
    </visual>
    <visual>
      <origin xyz="0.35 0 -0.15" rpy="1.5708 0 0" />
      <geometry>
        <cylinder radius="0.042" length="0.085" />
      </geometry>
      <material name="hub_metallic" />
    </visual>
    <visual>
      <origin xyz="0.35 -0.045 -0.15" rpy="1.5708 0 0" />
      <geometry>
        <cylinder radius="0.050" length="0.010" />
      </geometry>
      <material name="hub_metallic" />
    </visual>
    <visual>
      <origin xyz="0.32 0 -0.10" rpy="0 1.20 0" />
      <geometry>
        <box size="0.13 0.045 0.040" />
      </geometry>
      <material name="rocker_metallic" />
    </visual>
    <collision>
      <origin xyz="0.15 0 -0.06" rpy="0 0 0" />
      <geometry>
        <box size="0.44 0.07 0.055" />
      </geometry>
    </collision>
    <inertial>
      <mass value="2.8" />
      <origin xyz="0.15 0 -0.06" rpy="0 0 0" />
      <inertia ixx="0.00183" ixy="0.0" ixz="0.0" iyy="0.04586" iyz="0.0" izz="0.04630" />
    </inertial>
  </link>
  <joint name="right_rocker_joint" type="revolute">
    <parent link="base_link" />
    <child link="right_rocker" />
    <origin xyz="0 -0.30 0.0" rpy="0 0 0" />
    <axis xyz="0 1 0" />
    <limit lower="-0.5" upper="0.5" effort="200" velocity="1.5" />
    <dynamics damping="15.0" friction="2.0" spring_reference="0.0" spring_stiffness="150.0" />
  </joint>
  <link name="left_bogie">
    <visual>
      <origin xyz="0 0 0" rpy="1.5708 0 0" />
      <geometry>
        <cylinder radius="0.046" length="0.08" />
      </geometry>
      <material name="hub_metallic" />
    </visual>
    <visual>
      <origin xyz="0 0.043 0" rpy="1.5708 0 0" />
      <geometry>
        <cylinder radius="0.054" length="0.010" />
      </geometry>
      <material name="hub_metallic" />
    </visual>
    <visual>
      <origin xyz="0.025 0.016 -0.075" rpy="0 1.25 0" />
      <geometry>
        <box size="0.17 0.042 0.036" />
      </geometry>
      <material name="bogie_metallic">
        <color rgba="0.36 0.35 0.34 1.0" />
      </material>
    </visual>
    <visual>
      <origin xyz="-0.15 0.016 -0.075" rpy="0 -0.464 0" />
      <geometry>
        <box size="0.35 0.042 0.036" />
      </geometry>
      <material name="bogie_metallic" />
    </visual>
    <visual>
      <origin xyz="-0.125 0.016 -0.15" rpy="0 0 0" />
      <geometry>
        <box size="0.36 0.042 0.036" />
      </geometry>
      <material name="bogie_metallic" />
    </visual>
    <visual>
      <origin xyz="0.05 0 -0.15" rpy="1.5708 0 0" />
      <geometry>
        <cylinder radius="0.038" length="0.075" />
      </geometry>
      <material name="hub_metallic" />
    </visual>
    <visual>
      <origin xyz="0.05 0.040 -0.15" rpy="1.5708 0 0" />
      <geometry>
        <cylinder radius="0.046" length="0.010" />
      </geometry>
      <material name="hub_metallic" />
    </visual>
    <visual>
      <origin xyz="-0.30 0 -0.15" rpy="1.5708 0 0" />
      <geometry>
        <cylinder radius="0.038" length="0.075" />
      </geometry>
      <material name="hub_metallic" />
    </visual>
    <visual>
      <origin xyz="-0.30 0.040 -0.15" rpy="1.5708 0 0" />
      <geometry>
        <cylinder radius="0.046" length="0.010" />
      </geometry>
      <material name="hub_metallic" />
    </visual>
    <visual>
      <origin xyz="-0.08 0.016 -0.08" rpy="0 0 0" />
      <geometry>
        <box size="0.045 0.046 0.045" />
      </geometry>
      <material name="support_block" />
    </visual>
    <collision>
      <origin xyz="-0.125 0 -0.08" rpy="0 0 0" />
      <geometry>
        <box size="0.40 0.05 0.18" />
      </geometry>
    </collision>
    <inertial>
      <mass value="1.5" />
      <origin xyz="-0.10 0 -0.10" rpy="0 0 0" />
      <inertia ixx="0.00313" ixy="0.0" ixz="0.0" iyy="0.01813" iyz="0.0" izz="0.01563" />
    </inertial>
  </link>
  <joint name="left_bogie_joint" type="revolute">
    <parent link="left_rocker" />
    <child link="left_bogie" />
    <origin xyz="-0.05 0 0.0" rpy="0 0 0" />
    <axis xyz="0 1 0" />
    <limit lower="-0.6" upper="0.6" effort="100" velocity="1.5" />
    <dynamics damping="6.0" friction="1.5" />
  </joint>
  <link name="right_bogie">
    <visual>
      <origin xyz="0 0 0" rpy="1.5708 0 0" />
      <geometry>
        <cylinder radius="0.046" length="0.08" />
      </geometry>
      <material name="hub_metallic" />
    </visual>
    <visual>
      <origin xyz="0 -0.043 0" rpy="1.5708 0 0" />
      <geometry>
        <cylinder radius="0.054" length="0.010" />
      </geometry>
      <material name="hub_metallic" />
    </visual>
    <visual>
      <origin xyz="0.025 -0.016 -0.075" rpy="0 1.25 0" />
      <geometry>
        <box size="0.17 0.042 0.036" />
      </geometry>
      <material name="bogie_metallic" />
    </visual>
    <visual>
      <origin xyz="-0.15 -0.016 -0.075" rpy="0 -0.464 0" />
      <geometry>
        <box size="0.35 0.042 0.036" />
      </geometry>
      <material name="bogie_metallic" />
    </visual>
    <visual>
      <origin xyz="-0.125 -0.016 -0.15" rpy="0 0 0" />
      <geometry>
        <box size="0.36 0.042 0.036" />
      </geometry>
      <material name="bogie_metallic" />
    </visual>
    <visual>
      <origin xyz="0.05 0 -0.15" rpy="1.5708 0 0" />
      <geometry>
        <cylinder radius="0.038" length="0.075" />
      </geometry>
      <material name="hub_metallic" />
    </visual>
    <visual>
      <origin xyz="0.05 -0.040 -0.15" rpy="1.5708 0 0" />
      <geometry>
        <cylinder radius="0.046" length="0.010" />
      </geometry>
      <material name="hub_metallic" />
    </visual>
    <visual>
      <origin xyz="-0.30 0 -0.15" rpy="1.5708 0 0" />
      <geometry>
        <cylinder radius="0.038" length="0.075" />
      </geometry>
      <material name="hub_metallic" />
    </visual>
    <visual>
      <origin xyz="-0.30 -0.040 -0.15" rpy="1.5708 0 0" />
      <geometry>
        <cylinder radius="0.046" length="0.010" />
      </geometry>
      <material name="hub_metallic" />
    </visual>
    <visual>
      <origin xyz="-0.08 -0.016 -0.08" rpy="0 0 0" />
      <geometry>
        <box size="0.045 0.046 0.045" />
      </geometry>
      <material name="support_block" />
    </visual>
    <collision>
      <origin xyz="-0.125 0 -0.08" rpy="0 0 0" />
      <geometry>
        <box size="0.40 0.05 0.18" />
      </geometry>
    </collision>
    <inertial>
      <mass value="1.5" />
      <origin xyz="-0.10 0 -0.10" rpy="0 0 0" />
      <inertia ixx="0.00313" ixy="0.0" ixz="0.0" iyy="0.01813" iyz="0.0" izz="0.01563" />
    </inertial>
  </link>
  <joint name="right_bogie_joint" type="revolute">
    <parent link="right_rocker" />
    <child link="right_bogie" />
    <origin xyz="-0.05 0 0.0" rpy="0 0 0" />
    <axis xyz="0 1 0" />
    <limit lower="-0.6" upper="0.6" effort="100" velocity="1.5" />
    <dynamics damping="6.0" friction="1.5" />
  </joint>
  <link name="wheel_fl">
    <visual>
      <origin xyz="0 0 0" rpy="1.5708 0 0" />
      <geometry>
        <cylinder radius="0.15" length="0.095" />
      </geometry>
      <material name="tire_rubber">
        <color rgba="0.05 0.05 0.05 1.0" />
      </material>
    </visual>
    <visual>
      <origin xyz="0 0.048 0" rpy="1.5708 0 0" />
      <geometry>
        <cylinder radius="0.145" length="0.005" />
      </geometry>
      <material name="rim_alloy">
        <color rgba="0.50 0.50 0.52 1.0" />
      </material>
    </visual>
    <visual>
      <origin xyz="0 -0.048 0" rpy="1.5708 0 0" />
      <geometry>
        <cylinder radius="0.145" length="0.005" />
      </geometry>
      <material name="rim_alloy" />
    </visual>
    <visual>
      <origin xyz="0 0 0" rpy="1.5708 0 0" />
      <geometry>
        <cylinder radius="0.080" length="0.10" />
      </geometry>
      <material name="hub_alloy">
        <color rgba="0.48 0.48 0.50 1.0" />
      </material>
    </visual>
    <visual>
      <origin xyz="0 0 0" rpy="1.5708 0 0" />
      <geometry>
        <cylinder radius="0.038" length="0.12" />
      </geometry>
      <material name="axle_dark">
        <color rgba="0.08 0.08 0.08 1.0" />
      </material>
    </visual>
    <visual>
      <origin xyz="0 0.020 0" rpy="1.5708 0 0" />
      <geometry>
        <cylinder radius="0.152" length="0.008" />
      </geometry>
      <material name="tread_ring">
        <color rgba="0.12 0.12 0.12 1.0" />
      </material>
    </visual>
    <visual>
      <origin xyz="0 -0.020 0" rpy="1.5708 0 0" />
      <geometry>
        <cylinder radius="0.152" length="0.008" />
      </geometry>
      <material name="tread_ring" />
    </visual>
    <collision>
      <origin xyz="0 0 0" rpy="1.5708 0 0" />
      <geometry>
        <cylinder radius="0.15" length="0.09" />
      </geometry>
      <surface>
        <friction>
          <ode>
            <mu>2.0</mu>
            <mu2>0.05</mu2>
            <fdir1>1 0 0</fdir1>
            <slip1>0.02</slip1>
            <slip2>0.05</slip2>
          </ode>
        </friction>
        <contact>
          <ode>
            <kp>100000.0</kp>
            <kd>1.0</kd>
          </ode>
        </contact>
      </surface>
    </collision>
    <inertial>
      <mass value="0.3" />
      <origin xyz="0 0 0" rpy="0 0 0" />
      <inertia ixx="0.00189" ixy="0.0" ixz="0.0" iyy="0.00189" iyz="0.0" izz="0.00338" />
    </inertial>
  </link>
  <joint name="joint_wheel_fl" type="continuous">
    <parent link="left_rocker" />
    <child link="wheel_fl" />
    <origin xyz="0.35 0 -0.15" rpy="0 0 0" />
    <axis xyz="0 1 0" />
    <dynamics damping="0.2" friction="0.1" />
    <limit velocity="30.0" effort="400.0" />
  </joint>
  <link name="wheel_fr">
    <visual>
      <origin xyz="0 0 0" rpy="1.5708 0 0" />
      <geometry>
        <cylinder radius="0.15" length="0.095" />
      </geometry>
      <material name="tire_rubber" />
    </visual>
    <visual>
      <origin xyz="0 0.048 0" rpy="1.5708 0 0" />
      <geometry>
        <cylinder radius="0.145" length="0.005" />
      </geometry>
      <material name="rim_alloy" />
    </visual>
    <visual>
      <origin xyz="0 -0.048 0" rpy="1.5708 0 0" />
      <geometry>
        <cylinder radius="0.145" length="0.005" />
      </geometry>
      <material name="rim_alloy" />
    </visual>
    <visual>
      <origin xyz="0 0 0" rpy="1.5708 0 0" />
      <geometry>
        <cylinder radius="0.080" length="0.10" />
      </geometry>
      <material name="hub_alloy" />
    </visual>
    <visual>
      <origin xyz="0 0 0" rpy="1.5708 0 0" />
      <geometry>
        <cylinder radius="0.038" length="0.12" />
      </geometry>
      <material name="axle_dark" />
    </visual>
    <visual>
      <origin xyz="0 0.020 0" rpy="1.5708 0 0" />
      <geometry>
        <cylinder radius="0.152" length="0.008" />
      </geometry>
      <material name="tread_ring" />
    </visual>
    <visual>
      <origin xyz="0 -0.020 0" rpy="1.5708 0 0" />
      <geometry>
        <cylinder radius="0.152" length="0.008" />
      </geometry>
      <material name="tread_ring" />
    </visual>
    <collision>
      <origin xyz="0 0 0" rpy="1.5708 0 0" />
      <geometry>
        <cylinder radius="0.15" length="0.09" />
      </geometry>
      <surface>
        <friction>
          <ode>
            <mu>2.0</mu>
            <mu2>0.05</mu2>
            <fdir1>1 0 0</fdir1>
            <slip1>0.02</slip1>
            <slip2>0.05</slip2>
          </ode>
        </friction>
        <contact>
          <ode>
            <kp>100000.0</kp>
            <kd>1.0</kd>
          </ode>
        </contact>
      </surface>
    </collision>
    <inertial>
      <mass value="0.3" />
      <origin xyz="0 0 0" rpy="0 0 0" />
      <inertia ixx="0.00189" ixy="0.0" ixz="0.0" iyy="0.00189" iyz="0.0" izz="0.00338" />
    </inertial>
  </link>
  <joint name="joint_wheel_fr" type="continuous">
    <parent link="right_rocker" />
    <child link="wheel_fr" />
    <origin xyz="0.35 0 -0.15" rpy="0 0 0" />
    <axis xyz="0 1 0" />
    <dynamics damping="0.2" friction="0.1" />
    <limit velocity="30.0" effort="400.0" />
  </joint>
  <link name="wheel_ml">
    <visual>
      <origin xyz="0 0 0" rpy="1.5708 0 0" />
      <geometry>
        <cylinder radius="0.15" length="0.095" />
      </geometry>
      <material name="tire_rubber" />
    </visual>
    <visual>
      <origin xyz="0 0.048 0" rpy="1.5708 0 0" />
      <geometry>
        <cylinder radius="0.145" length="0.005" />
      </geometry>
      <material name="rim_alloy" />
    </visual>
    <visual>
      <origin xyz="0 -0.048 0" rpy="1.5708 0 0" />
      <geometry>
        <cylinder radius="0.145" length="0.005" />
      </geometry>
      <material name="rim_alloy" />
    </visual>
    <visual>
      <origin xyz="0 0 0" rpy="1.5708 0 0" />
      <geometry>
        <cylinder radius="0.080" length="0.10" />
      </geometry>
      <material name="hub_alloy" />
    </visual>
    <visual>
      <origin xyz="0 0 0" rpy="1.5708 0 0" />
      <geometry>
        <cylinder radius="0.038" length="0.12" />
      </geometry>
      <material name="axle_dark" />
    </visual>
    <visual>
      <origin xyz="0 0.020 0" rpy="1.5708 0 0" />
      <geometry>
        <cylinder radius="0.152" length="0.008" />
      </geometry>
      <material name="tread_ring" />
    </visual>
    <visual>
      <origin xyz="0 -0.020 0" rpy="1.5708 0 0" />
      <geometry>
        <cylinder radius="0.152" length="0.008" />
      </geometry>
      <material name="tread_ring" />
    </visual>
    <collision>
      <origin xyz="0 0 0" rpy="1.5708 0 0" />
      <geometry>
        <cylinder radius="0.15" length="0.09" />
      </geometry>
      <surface>
        <friction>
          <ode>
            <mu>2.0</mu>
            <mu2>0.05</mu2>
            <fdir1>1 0 0</fdir1>
            <slip1>0.02</slip1>
            <slip2>0.05</slip2>
          </ode>
        </friction>
        <contact>
          <ode>
            <kp>100000.0</kp>
            <kd>1.0</kd>
          </ode>
        </contact>
      </surface>
    </collision>
    <inertial>
      <mass value="0.3" />
      <origin xyz="0 0 0" rpy="0 0 0" />
      <inertia ixx="0.00189" ixy="0.0" ixz="0.0" iyy="0.00189" iyz="0.0" izz="0.00338" />
    </inertial>
  </link>
  <joint name="joint_wheel_ml" type="continuous">
    <parent link="left_bogie" />
    <child link="wheel_ml" />
    <origin xyz="0.05 0 -0.15" rpy="0 0 0" />
    <axis xyz="0 1 0" />
    <dynamics damping="0.2" friction="0.1" />
    <limit velocity="30.0" effort="400.0" />
  </joint>
  <link name="wheel_mr">
    <visual>
      <origin xyz="0 0 0" rpy="1.5708 0 0" />
      <geometry>
        <cylinder radius="0.15" length="0.095" />
      </geometry>
      <material name="tire_rubber" />
    </visual>
    <visual>
      <origin xyz="0 0.048 0" rpy="1.5708 0 0" />
      <geometry>
        <cylinder radius="0.145" length="0.005" />
      </geometry>
      <material name="rim_alloy" />
    </visual>
    <visual>
      <origin xyz="0 -0.048 0" rpy="1.5708 0 0" />
      <geometry>
        <cylinder radius="0.145" length="0.005" />
      </geometry>
      <material name="rim_alloy" />
    </visual>
    <visual>
      <origin xyz="0 0 0" rpy="1.5708 0 0" />
      <geometry>
        <cylinder radius="0.080" length="0.10" />
      </geometry>
      <material name="hub_alloy" />
    </visual>
    <visual>
      <origin xyz="0 0 0" rpy="1.5708 0 0" />
      <geometry>
        <cylinder radius="0.038" length="0.12" />
      </geometry>
      <material name="axle_dark" />
    </visual>
    <visual>
      <origin xyz="0 0.020 0" rpy="1.5708 0 0" />
      <geometry>
        <cylinder radius="0.152" length="0.008" />
      </geometry>
      <material name="tread_ring" />
    </visual>
    <visual>
      <origin xyz="0 -0.020 0" rpy="1.5708 0 0" />
      <geometry>
        <cylinder radius="0.152" length="0.008" />
      </geometry>
      <material name="tread_ring" />
    </visual>
    <collision>
      <origin xyz="0 0 0" rpy="1.5708 0 0" />
      <geometry>
        <cylinder radius="0.15" length="0.09" />
      </geometry>
      <surface>
        <friction>
          <ode>
            <mu>2.0</mu>
            <mu2>0.05</mu2>
            <fdir1>1 0 0</fdir1>
            <slip1>0.02</slip1>
            <slip2>0.05</slip2>
          </ode>
        </friction>
        <contact>
          <ode>
            <kp>100000.0</kp>
            <kd>1.0</kd>
          </ode>
        </contact>
      </surface>
    </collision>
    <inertial>
      <mass value="0.3" />
      <origin xyz="0 0 0" rpy="0 0 0" />
      <inertia ixx="0.00189" ixy="0.0" ixz="0.0" iyy="0.00189" iyz="0.0" izz="0.00338" />
    </inertial>
  </link>
  <joint name="joint_wheel_mr" type="continuous">
    <parent link="right_bogie" />
    <child link="wheel_mr" />
    <origin xyz="0.05 0 -0.15" rpy="0 0 0" />
    <axis xyz="0 1 0" />
    <dynamics damping="0.2" friction="0.1" />
    <limit velocity="30.0" effort="400.0" />
  </joint>
  <link name="wheel_rl">
    <visual>
      <origin xyz="0 0 0" rpy="1.5708 0 0" />
      <geometry>
        <cylinder radius="0.15" length="0.095" />
      </geometry>
      <material name="tire_rubber" />
    </visual>
    <visual>
      <origin xyz="0 0.048 0" rpy="1.5708 0 0" />
      <geometry>
        <cylinder radius="0.145" length="0.005" />
      </geometry>
      <material name="rim_alloy" />
    </visual>
    <visual>
      <origin xyz="0 -0.048 0" rpy="1.5708 0 0" />
      <geometry>
        <cylinder radius="0.145" length="0.005" />
      </geometry>
      <material name="rim_alloy" />
    </visual>
    <visual>
      <origin xyz="0 0 0" rpy="1.5708 0 0" />
      <geometry>
        <cylinder radius="0.080" length="0.10" />
      </geometry>
      <material name="hub_alloy" />
    </visual>
    <visual>
      <origin xyz="0 0 0" rpy="1.5708 0 0" />
      <geometry>
        <cylinder radius="0.038" length="0.12" />
      </geometry>
      <material name="axle_dark" />
    </visual>
    <visual>
      <origin xyz="0 0.020 0" rpy="1.5708 0 0" />
      <geometry>
        <cylinder radius="0.152" length="0.008" />
      </geometry>
      <material name="tread_ring" />
    </visual>
    <visual>
      <origin xyz="0 -0.020 0" rpy="1.5708 0 0" />
      <geometry>
        <cylinder radius="0.152" length="0.008" />
      </geometry>
      <material name="tread_ring" />
    </visual>
    <collision>
      <origin xyz="0 0 0" rpy="1.5708 0 0" />
      <geometry>
        <cylinder radius="0.15" length="0.09" />
      </geometry>
      <surface>
        <friction>
          <ode>
            <mu>2.0</mu>
            <mu2>0.05</mu2>
            <fdir1>1 0 0</fdir1>
            <slip1>0.02</slip1>
            <slip2>0.05</slip2>
          </ode>
        </friction>
        <contact>
          <ode>
            <kp>100000.0</kp>
            <kd>1.0</kd>
          </ode>
        </contact>
      </surface>
    </collision>
    <inertial>
      <mass value="0.3" />
      <origin xyz="0 0 0" rpy="0 0 0" />
      <inertia ixx="0.00189" ixy="0.0" ixz="0.0" iyy="0.00189" iyz="0.0" izz="0.00338" />
    </inertial>
  </link>
  <joint name="joint_wheel_rl" type="continuous">
    <parent link="left_bogie" />
    <child link="wheel_rl" />
    <origin xyz="-0.30 0 -0.15" rpy="0 0 0" />
    <axis xyz="0 1 0" />
    <dynamics damping="0.2" friction="0.1" />
    <limit velocity="30.0" effort="400.0" />
  </joint>
  <link name="wheel_rr">
    <visual>
      <origin xyz="0 0 0" rpy="1.5708 0 0" />
      <geometry>
        <cylinder radius="0.15" length="0.095" />
      </geometry>
      <material name="tire_rubber" />
    </visual>
    <visual>
      <origin xyz="0 0.048 0" rpy="1.5708 0 0" />
      <geometry>
        <cylinder radius="0.145" length="0.005" />
      </geometry>
      <material name="rim_alloy" />
    </visual>
    <visual>
      <origin xyz="0 -0.048 0" rpy="1.5708 0 0" />
      <geometry>
        <cylinder radius="0.145" length="0.005" />
      </geometry>
      <material name="rim_alloy" />
    </visual>
    <visual>
      <origin xyz="0 0 0" rpy="1.5708 0 0" />
      <geometry>
        <cylinder radius="0.080" length="0.10" />
      </geometry>
      <material name="hub_alloy" />
    </visual>
    <visual>
      <origin xyz="0 0 0" rpy="1.5708 0 0" />
      <geometry>
        <cylinder radius="0.038" length="0.12" />
      </geometry>
      <material name="axle_dark" />
    </visual>
    <visual>
      <origin xyz="0 0.020 0" rpy="1.5708 0 0" />
      <geometry>
        <cylinder radius="0.152" length="0.008" />
      </geometry>
      <material name="tread_ring" />
    </visual>
    <visual>
      <origin xyz="0 -0.020 0" rpy="1.5708 0 0" />
      <geometry>
        <cylinder radius="0.152" length="0.008" />
      </geometry>
      <material name="tread_ring" />
    </visual>
    <collision>
      <origin xyz="0 0 0" rpy="1.5708 0 0" />
      <geometry>
        <cylinder radius="0.15" length="0.09" />
      </geometry>
      <surface>
        <friction>
          <ode>
            <mu>2.0</mu>
            <mu2>0.05</mu2>
            <fdir1>1 0 0</fdir1>
            <slip1>0.02</slip1>
            <slip2>0.05</slip2>
          </ode>
        </friction>
        <contact>
          <ode>
            <kp>100000.0</kp>
            <kd>1.0</kd>
          </ode>
        </contact>
      </surface>
    </collision>
    <inertial>
      <mass value="0.3" />
      <origin xyz="0 0 0" rpy="0 0 0" />
      <inertia ixx="0.00189" ixy="0.0" ixz="0.0" iyy="0.00189" iyz="0.0" izz="0.00338" />
    </inertial>
  </link>
  <joint name="joint_wheel_rr" type="continuous">
    <parent link="right_bogie" />
    <child link="wheel_rr" />
    <origin xyz="-0.30 0 -0.15" rpy="0 0 0" />
    <axis xyz="0 1 0" />
    <dynamics damping="0.2" friction="0.1" />
    <limit velocity="30.0" effort="400.0" />
  </joint>
  <gazebo reference="left_rocker_joint">
    <implicitSpringDamper>1</implicitSpringDamper>
    <springStiffness>150.0</springStiffness>
    <springReference>0.0</springReference>
  </gazebo>
  <gazebo reference="right_rocker_joint">
    <implicitSpringDamper>1</implicitSpringDamper>
    <springStiffness>150.0</springStiffness>
    <springReference>0.0</springReference>
  </gazebo>
  <gazebo reference="base_link">
    <material>Gazebo/White</material>
  </gazebo>
  <gazebo reference="camera_mast">
    <material>Gazebo/Grey</material>
  </gazebo>
  <gazebo reference="antenna">
    <material>Gazebo/Grey</material>
  </gazebo>
  <gazebo reference="sensor_box">
    <material>Gazebo/DarkGrey</material>
  </gazebo>
  <gazebo reference="left_rocker">
    <material>Gazebo/Grey</material>
  </gazebo>
  <gazebo reference="right_rocker">
    <material>Gazebo/Grey</material>
  </gazebo>
  <gazebo reference="left_bogie">
    <material>Gazebo/DarkGrey</material>
  </gazebo>
  <gazebo reference="right_bogie">
    <material>Gazebo/DarkGrey</material>
  </gazebo>
  <gazebo reference="wheel_fl">
    <material>Gazebo/FlatBlack</material>
    <mu1>2.0</mu1>
    <mu2>0.15</mu2>
    <kp>1000000.0</kp>
    <kd>100.0</kd>
    <minDepth>0.001</minDepth>
    <maxVel>1.0</maxVel>
  </gazebo>
  <gazebo reference="wheel_fr">
    <material>Gazebo/FlatBlack</material>
    <mu1>2.0</mu1>
    <mu2>0.15</mu2>
    <kp>1000000.0</kp>
    <kd>100.0</kd>
    <minDepth>0.001</minDepth>
    <maxVel>1.0</maxVel>
  </gazebo>
  <gazebo reference="wheel_ml">
    <material>Gazebo/FlatBlack</material>
    <mu1>2.0</mu1>
    <mu2>0.15</mu2>
    <kp>1000000.0</kp>
    <kd>100.0</kd>
    <minDepth>0.001</minDepth>
    <maxVel>1.0</maxVel>
  </gazebo>
  <gazebo reference="wheel_mr">
    <material>Gazebo/FlatBlack</material>
    <mu1>2.0</mu1>
    <mu2>0.15</mu2>
    <kp>1000000.0</kp>
    <kd>100.0</kd>
    <minDepth>0.001</minDepth>
    <maxVel>1.0</maxVel>
  </gazebo>
  <gazebo reference="wheel_rl">
    <material>Gazebo/FlatBlack</material>
    <mu1>2.0</mu1>
    <mu2>0.15</mu2>
    <kp>1000000.0</kp>
    <kd>100.0</kd>
    <minDepth>0.001</minDepth>
    <maxVel>1.0</maxVel>
  </gazebo>
  <gazebo reference="wheel_rr">
    <material>Gazebo/FlatBlack</material>
    <mu1>2.0</mu1>
    <mu2>0.15</mu2>
    <kp>1000000.0</kp>
    <kd>100.0</kd>
    <minDepth>0.001</minDepth>
    <maxVel>1.0</maxVel>
  </gazebo>
  <link name="imu_link">
    <visual>
      <origin xyz="0 0 0" rpy="0 0 0" />
      <geometry>
        <box size="0.04 0.04 0.02" />
      </geometry>
      <material name="imu_dark">
        <color rgba="0.10 0.10 0.10 1.0" />
      </material>
    </visual>
    <collision>
      <origin xyz="0 0 0" rpy="0 0 0" />
      <geometry>
        <box size="0.04 0.04 0.02" />
      </geometry>
    </collision>
    <inertial>
      <mass value="0.05" />
      <origin xyz="0 0 0" rpy="0 0 0" />
      <inertia ixx="0.000008" ixy="0.0" ixz="0.0" iyy="0.000008" iyz="0.0" izz="0.000013" />
    </inertial>
  </link>
  <joint name="imu_joint" type="fixed">
    <parent link="base_link" />
    <child link="imu_link" />
    <origin xyz="0 0 0.12" rpy="0 0 0" />
  </joint>
  <gazebo reference="imu_link">
    <sensor name="imu_sensor" type="imu">
      <update_rate>100</update_rate>
      <always_on>true</always_on>
      <topic>/imu</topic>
      <gz_frame_id>imu_link</gz_frame_id>
      <imu>
        <angular_velocity>
          <x>
            <noise type="gaussian">
              <mean>0.0</mean>
              <stddev>0.002</stddev>
            </noise>
          </x>
          <y>
            <noise type="gaussian">
              <mean>0.0</mean>
              <stddev>0.002</stddev>
            </noise>
          </y>
          <z>
            <noise type="gaussian">
              <mean>0.0</mean>
              <stddev>0.002</stddev>
            </noise>
          </z>
        </angular_velocity>
        <linear_acceleration>
          <x>
            <noise type="gaussian">
              <mean>0.0</mean>
              <stddev>0.017</stddev>
            </noise>
          </x>
          <y>
            <noise type="gaussian">
              <mean>0.0</mean>
              <stddev>0.017</stddev>
            </noise>
          </y>
          <z>
            <noise type="gaussian">
              <mean>0.0</mean>
              <stddev>0.017</stddev>
            </noise>
          </z>
        </linear_acceleration>
      </imu>
    </sensor>
  </gazebo>
  <link name="lidar_link">
    <visual>
      <origin xyz="0 0 0" rpy="0 0 0" />
      <geometry>
        <cylinder radius="0.05" length="0.06" />
      </geometry>
      <material name="lidar_black">
        <color rgba="0.05 0.05 0.05 1.0" />
      </material>
    </visual>
    <collision>
      <origin xyz="0 0 0" rpy="0 0 0" />
      <geometry>
        <cylinder radius="0.05" length="0.06" />
      </geometry>
    </collision>
    <inertial>
      <mass value="0.15" />
      <origin xyz="0 0 0" rpy="0 0 0" />
      <inertia ixx="0.000139" ixy="0.0" ixz="0.0" iyy="0.000139" iyz="0.0" izz="0.000188" />
    </inertial>
  </link>
  <joint name="lidar_joint" type="fixed">
    <parent link="base_link" />
    <child link="lidar_link" />
    <origin xyz="0 0 0.30" rpy="0 0 0" />
  </joint>
  <gazebo reference="lidar_link">
    <sensor name="lidar" type="gpu_lidar">
      <update_rate>15</update_rate>
      <always_on>true</always_on>
      <visualize>false</visualize>
      <topic>/scan</topic>
      <gz_frame_id>lidar_link</gz_frame_id>
      <ray>
        <scan>
          <horizontal>
            <samples>1080</samples>
            <resolution>1</resolution>
            <min_angle>-3.14159</min_angle>
            <max_angle>3.14159</max_angle>
          </horizontal>
        </scan>
        <range>
          <min>0.10</min>
          <max>20.0</max>
          <resolution>0.01</resolution>
        </range>
        <noise>
          <type>gaussian</type>
          <mean>0.0</mean>
          <stddev>0.01</stddev>
        </noise>
      </ray>
    </sensor>
  </gazebo>
  <gazebo>
    <plugin filename="gz-sim-joint-state-publisher-system" name="gz::sim::systems::JointStatePublisher">
      <update_rate>100</update_rate>
      <joint_name>left_rocker_joint</joint_name>
      <joint_name>right_rocker_joint</joint_name>
      <joint_name>left_bogie_joint</joint_name>
      <joint_name>right_bogie_joint</joint_name>
      <joint_name>joint_wheel_fl</joint_name>
      <joint_name>joint_wheel_fr</joint_name>
      <joint_name>joint_wheel_ml</joint_name>
      <joint_name>joint_wheel_mr</joint_name>
      <joint_name>joint_wheel_rl</joint_name>
      <joint_name>joint_wheel_rr</joint_name>
    </plugin>
  </gazebo>
  <gazebo>
    <plugin filename="gz-sim-diff-drive-system" name="gz::sim::systems::DiffDrive">
      <left_joint>joint_wheel_fl</left_joint>
      <left_joint>joint_wheel_ml</left_joint>
      <left_joint>joint_wheel_rl</left_joint>
      <right_joint>joint_wheel_fr</right_joint>
      <right_joint>joint_wheel_mr</right_joint>
      <right_joint>joint_wheel_rr</right_joint>
      <wheel_separation>0.60</wheel_separation>
      <wheel_radius>0.15</wheel_radius>
      <topic>/cmd_vel</topic>
      <update_rate>100</update_rate>
      <cmd_vel_timeout>0.1</cmd_vel_timeout>
      <max_acceleration>5.0</max_acceleration>
      <max_linear_acceleration>10.0</max_linear_acceleration>
      <max_angular_acceleration>15.0</max_angular_acceleration>
      <max_velocity>3.0</max_velocity>
      <odom_topic>/odom</odom_topic>
      <tf_topic>/tf</tf_topic>
      <odom_publish_frequency>100</odom_publish_frequency>
      <odom_frame>odom</odom_frame>
      <robot_base_frame>base_link</robot_base_frame>
      <publish_odom>true</publish_odom>
      <publish_odom_tf>true</publish_odom_tf>
      <publish_wheel_tf>false</publish_wheel_tf>
      <frame_id>odom</frame_id>
      <child_frame_id>base_link</child_frame_id>
    </plugin>
  </gazebo>
</robot>
